<robot
  name="BHD280_URDF">
  <link
    name="base_link">
    <inertial>
      <origin
        xyz="1.53444878605417E-05 0.00277693660903533 0.0352882290973172"
        rpy="0 0 0" />
      <mass
        value="0.377966381303299" />
      <inertia
        ixx="0.0004273263730186"
        ixy="2.6443337984506E-07"
        ixz="2.02908063714993E-07"
        iyy="0.000361316175967098"
        iyz="3.07926873276031E-05"
        izz="0.000376798128588446" />
    </inertial>
    <visual>
      <origin
        xyz="0 0 0"
        rpy="0 0 0" />
      <geometry>
        <mesh
          filename="package://BHD280_URDF/meshes/base_link.STL" />
      </geometry>
      <material
        name="">
        <color
          rgba="0.752941176470588 0.752941176470588 0.752941176470588 1" />
      </material>
    </visual>
    <collision>
      <origin
        xyz="0 0 0"
        rpy="0 0 0" />
      <geometry>
        <mesh
          filename="package://BHD280_URDF/meshes/base_link.STL" />
      </geometry>
    </collision>
  </link>
  <link
    name="finger0_0">
    <inertial>
      <origin
        xyz="0.0288648917008998 -9.98379746691008E-05 -0.0167746522430198"
        rpy="0 0 0" />
      <mass
        value="56143.0626955765" />
      <inertia
        ixx="10.4484040652085"
        ixy="-0.11786144821989"
        ixz="5.31613760585343"
        iyy="33.9552353012776"
        iyz="-0.0780041192837512"
        izz="29.3669090518615" />
    </inertial>
    <visual>
      <origin
        xyz="0 0 0"
        rpy="0 0 0" />
      <geometry>
        <mesh
          filename="package://BHD280_URDF/meshes/finger0_0.STL" />
      </geometry>
      <material
        name="">
        <color
          rgba="0.752941176470588 0.752941176470588 0.752941176470588 1" />
      </material>
    </visual>
    <collision>
      <origin
        xyz="0 0 0"
        rpy="0 0 0" />
      <geometry>
        <mesh
          filename="package://BHD280_URDF/meshes/finger0_0.STL" />
      </geometry>
    </collision>
  </link>
  <joint
    name="j00"
    type="continuous">
    <origin
      xyz="-0.025 0 0.0754000000000003"
      rpy="-9.27906974436996E-30 -2.56739074444568E-16 -1.5707963267949" />
    <parent
      link="base_link" />
    <child
      link="finger0_0" />
    <axis
      xyz="0 0 -1" />
  </joint>
  <link
    name="finger0_1">
    <inertial>
      <origin
        xyz="0.0309181761355441 0.0019693024932544 5.66301573335787E-05"
        rpy="0 0 0" />
      <mass
        value="31321.1214212939" />
      <inertia
        ixx="2.18512832127284"
        ixy="0.844484268309693"
        ixz="0.0135401272400817"
        iyy="17.3596441998536"
        iyz="0.00112669216751589"
        izz="17.7656644395659" />
    </inertial>
    <visual>
      <origin
        xyz="0 0 0"
        rpy="0 0 0" />
      <geometry>
        <mesh
          filename="package://BHD280_URDF/meshes/finger0_1.STL" />
      </geometry>
      <material
        name="">
        <color
          rgba="0.752941176470588 0.752941176470588 0.752941176470588 1" />
      </material>
    </visual>
    <collision>
      <origin
        xyz="0 0 0"
        rpy="0 0 0" />
      <geometry>
        <mesh
          filename="package://BHD280_URDF/meshes/finger0_1.STL" />
      </geometry>
    </collision>
  </link>
  <joint
    name="j01"
    type="continuous">
    <origin
      xyz="0.0500000000000005 0.000799999999999978 0"
      rpy="1.5707963267949 0 0" />
    <parent
      link="finger0_0" />
    <child
      link="finger0_1" />
    <axis
      xyz="0 0 1" />
  </joint>
  <link
    name="finger0_2">
    <inertial>
      <origin
        xyz="0.0253322571839626 0.00167106362872827 0.000102872216676219"
        rpy="0 0 0" />
      <mass
        value="19342.3312257343" />
      <inertia
        ixx="1.3063001219566"
        ixy="0.244495902363989"
        ixz="-0.0476463473584932"
        iyy="6.45563111007667"
        iyz="-0.0029970336947913"
        izz="5.99395386650427" />
    </inertial>
    <visual>
      <origin
        xyz="0 0 0"
        rpy="0 0 0" />
      <geometry>
        <mesh
          filename="package://BHD280_URDF/meshes/finger0_2.STL" />
      </geometry>
      <material
        name="">
        <color
          rgba="0.898039215686275 0.917647058823529 0.929411764705882 1" />
      </material>
    </visual>
    <collision>
      <origin
        xyz="0 0 0"
        rpy="0 0 0" />
      <geometry>
        <mesh
          filename="package://BHD280_URDF/meshes/finger0_2.STL" />
      </geometry>
    </collision>
  </link>
  <joint
    name="j02"
    type="continuous">
    <origin
      xyz="0.0699356847396221 0.003 0.000200000000006962"
      rpy="-3.77533479986348E-14 -4.45260733378639E-14 0.698131700822416" />
    <parent
      link="finger0_1" />
    <child
      link="finger0_2" />
    <axis
      xyz="0 0 1" />
  </joint>
  <link
    name="finger1_0">
    <inertial>
      <origin
        xyz="0.0287663539170761 -9.98379746692049E-05 -0.016943075668142"
        rpy="0 0 0" />
      <mass
        value="56143.0626955765" />
      <inertia
        ixx="10.3869077355928"
        ixy="-0.118315354672022"
        ixz="5.20520111305201"
        iyy="33.9552353012776"
        iyz="-0.0773139085196083"
        izz="29.4284053814771" />
    </inertial>
    <visual>
      <origin
        xyz="0 0 0"
        rpy="0 0 0" />
      <geometry>
        <mesh
          filename="package://BHD280_URDF/meshes/finger1_0.STL" />
      </geometry>
      <material
        name="">
        <color
          rgba="0.752941176470588 0.752941176470588 0.752941176470588 1" />
      </material>
    </visual>
    <collision>
      <origin
        xyz="0 0 0"
        rpy="0 0 0" />
      <geometry>
        <mesh
          filename="package://BHD280_URDF/meshes/finger1_0.STL" />
      </geometry>
    </collision>
  </link>
  <joint
    name="j10"
    type="continuous">
    <origin
      xyz="0.025 0 0.0754000000000004"
      rpy="-9.28709853220239E-30 -0.00584484835748173 -1.5707963267949" />
    <parent
      link="base_link" />
    <child
      link="finger1_0" />
    <axis
      xyz="-0.00584481507867448 0 -0.999982918922466" />
  </joint>
  <link
    name="finger1_1">
    <inertial>
      <origin
        xyz="0.0309181761449676 0.00196930210221455 5.66301859537474E-05"
        rpy="0 0 0" />
      <mass
        value="31321.1215499126" />
      <inertia
        ixx="2.18512832967327"
        ixy="0.844484155951963"
        ixz="0.0135401335439361"
        iyy="17.3596442221312"
        iyz="0.00112673821434552"
        izz="17.7656644132238" />
    </inertial>
    <visual>
      <origin
        xyz="0 0 0"
        rpy="0 0 0" />
      <geometry>
        <mesh
          filename="package://BHD280_URDF/meshes/finger1_1.STL" />
      </geometry>
      <material
        name="">
        <color
          rgba="0.752941176470588 0.752941176470588 0.752941176470588 1" />
      </material>
    </visual>
    <collision>
      <origin
        xyz="0 0 0"
        rpy="0 0 0" />
      <geometry>
        <mesh
          filename="package://BHD280_URDF/meshes/finger1_1.STL" />
      </geometry>
    </collision>
  </link>
  <joint
    name="j11"
    type="continuous">
    <origin
      xyz="0.0499991459461259 0.000799999999999367 -0.000292240753933679"
      rpy="1.5707963267949 0 -4.93038065763132E-32" />
    <parent
      link="finger1_0" />
    <child
      link="finger1_1" />
    <axis
      xyz="0 0 1" />
  </joint>
  <link
    name="finger1_2">
    <inertial>
      <origin
        xyz="0.0253322572246781 0.00167106357335604 0.000102872216738797"
        rpy="0 0 0" />
      <mass
        value="19342.3313295693" />
      <inertia
        ixx="1.30630012953801"
        ixy="0.244495900353317"
        ixz="-0.0476463484401436"
        iyy="6.45563113593989"
        iyz="-0.0029970403369865"
        izz="5.99395390717116" />
    </inertial>
    <visual>
      <origin
        xyz="0 0 0"
        rpy="0 0 0" />
      <geometry>
        <mesh
          filename="package://BHD280_URDF/meshes/finger1_2.STL" />
      </geometry>
      <material
        name="">
        <color
          rgba="0.898039215686275 0.917647058823529 0.929411764705882 1" />
      </material>
    </visual>
    <collision>
      <origin
        xyz="0 0 0"
        rpy="0 0 0" />
      <geometry>
        <mesh
          filename="package://BHD280_URDF/meshes/finger1_2.STL" />
      </geometry>
    </collision>
  </link>
  <joint
    name="j12"
    type="continuous">
    <origin
      xyz="0.0699356847396194 0.00300000000000614 0.000199999999999378"
      rpy="1.95799899548702E-16 2.29686057908074E-16 0.700079983587682" />
    <parent
      link="finger1_1" />
    <child
      link="finger1_2" />
    <axis
      xyz="0 0 1" />
  </joint>
  <link
    name="finger2_1">
    <inertial>
      <origin
        xyz="0.0309181761355441 0.00196930249325443 5.66301573335818E-05"
        rpy="0 0 0" />
      <mass
        value="31321.1214212939" />
      <inertia
        ixx="2.18512832127284"
        ixy="0.844484268309697"
        ixz="0.013540127240082"
        iyy="17.3596441998537"
        iyz="0.00112669216751514"
        izz="17.7656644395659" />
    </inertial>
    <visual>
      <origin
        xyz="0 0 0"
        rpy="0 0 0" />
      <geometry>
        <mesh
          filename="package://BHD280_URDF/meshes/finger2_1.STL" />
      </geometry>
      <material
        name="">
        <color
          rgba="0.752941176470588 0.752941176470588 0.752941176470588 1" />
      </material>
    </visual>
    <collision>
      <origin
        xyz="0 0 0"
        rpy="0 0 0" />
      <geometry>
        <mesh
          filename="package://BHD280_URDF/meshes/finger2_1.STL" />
      </geometry>
    </collision>
  </link>
  <joint
    name="j21"
    type="continuous">
    <origin
      xyz="-0.000799999999999992 0.05 0.0754000000000003"
      rpy="1.5707963267949 2.77555756156289E-17 1.5707963267949" />
    <parent
      link="base_link" />
    <child
      link="finger2_1" />
    <axis
      xyz="0 0 1" />
  </joint>
  <link
    name="finger2_2">
    <inertial>
      <origin
        xyz="0.0253322571839626 0.00167106362872825 0.000102872216676229"
        rpy="0 0 0" />
      <mass
        value="19342.3312257343" />
      <inertia
        ixx="1.3063001219566"
        ixy="0.24449590236399"
        ixz="-0.0476463473584918"
        iyy="6.45563111007669"
        iyz="-0.00299703369479218"
        izz="5.99395386650428" />
    </inertial>
    <visual>
      <origin
        xyz="0 0 0"
        rpy="0 0 0" />
      <geometry>
        <mesh
          filename="package://BHD280_URDF/meshes/finger2_2.STL" />
      </geometry>
      <material
        name="">
        <color
          rgba="0.898039215686275 0.917647058823529 0.929411764705882 1" />
      </material>
    </visual>
    <collision>
      <origin
        xyz="0 0 0"
        rpy="0 0 0" />
      <geometry>
        <mesh
          filename="package://BHD280_URDF/meshes/finger2_2.STL" />
      </geometry>
    </collision>
  </link>
  <joint
    name="j22"
    type="continuous">
    <origin
      xyz="0.0699356847396236 0.00300000000000011 0.000199999999999993"
      rpy="5.6276902721421E-16 5.75421399737176E-16 0.698131700797743" />
    <parent
      link="finger2_1" />
    <child
      link="finger2_2" />
    <axis
      xyz="0 0 1" />
  </joint>
</robot>