<robot
  name="HERB_BASE_URDF">
  <link
    name="herb_base">
    <inertial>
      <origin
        xyz="-0.0809070109190441 0.00802979500174428 0.350730944533607"
        rpy="0 0 0" />
      <mass
        value="118.073177712457" />
      <inertia
        ixx="9.67519962999918"
        ixy="-0.109435937013395"
        ixz="-2.47830472086505"
        iyy="10.2624016904412"
        iyz="0.237380904381388"
        izz="5.27444955638408" />
    </inertial>
    <visual>
      <origin
        xyz="0 0 0"
        rpy="0 0 0" />
      <geometry>
        <mesh
          filename="package://HERB_BASE_URDF/meshes/herb_base.STL" />
      </geometry>
      <material
        name="">
        <color
          rgba="0.792156862745098 0.819607843137255 0.933333333333333 1" />
      </material>
    </visual>
    <collision>
      <origin
        xyz="0 0 0"
        rpy="0 0 0" />
      <geometry>
        <mesh
          filename="package://HERB_BASE_URDF/meshes/herb_base.STL" />
      </geometry>
    </collision>
  </link>
  <link
    name="segway_left">
    <inertial>
      <origin
        xyz="1.46252801536129E-12 4.14215883814961E-12 0.0471293756901144"
        rpy="0 0 0" />
      <mass
        value="6.7355511743555" />
      <inertia
        ixx="0.092576479522193"
        ixy="-2.98851956896402E-06"
        ixz="1.06719826189901E-09"
        iyy="0.0925839088729686"
        iyz="3.02916843459004E-09"
        izz="0.178365793214305" />
    </inertial>
    <visual>
      <origin
        xyz="0 0 0"
        rpy="0 0 0" />
      <geometry>
        <mesh
          filename="package://HERB_BASE_URDF/meshes/segway_left.STL" />
      </geometry>
      <material
        name="">
        <color
          rgba="0.792156862745098 0.819607843137255 0.933333333333333 1" />
      </material>
    </visual>
    <collision>
      <origin
        xyz="0 0 0"
        rpy="0 0 0" />
      <geometry>
        <mesh
          filename="package://HERB_BASE_URDF/meshes/segway_left.STL" />
      </geometry>
    </collision>
  </link>
  <joint
    name="segway_left"
    type="continuous">
    <origin
      xyz="0 0.231771918932663 0.23158735611353"
      rpy="-1.5707963267949 -0.115508699092541 0" />
    <parent
      link="herb_base" />
    <child
      link="segway_left" />
    <axis
      xyz="0 0 -1" />
  </joint>
  <link
    name="segway_right">
    <inertial>
      <origin
        xyz="-1.06858966120171E-15 4.39881464586733E-12 0.0471293756901144"
        rpy="0 0 0" />
      <mass
        value="6.7355511743555" />
      <inertia
        ixx="0.0925754265920571"
        ixy="-1.49287030220407E-10"
        ixz="-1.57470256113964E-16"
        iyy="0.0925849618031043"
        iyz="3.2116621292267E-09"
        izz="0.178365793214305" />
    </inertial>
    <visual>
      <origin
        xyz="0 0 0"
        rpy="0 0 0" />
      <geometry>
        <mesh
          filename="package://HERB_BASE_URDF/meshes/segway_right.STL" />
      </geometry>
      <material
        name="">
        <color
          rgba="0.792156862745098 0.819607843137255 0.933333333333333 1" />
      </material>
    </visual>
    <collision>
      <origin
        xyz="0 0 0"
        rpy="0 0 0" />
      <geometry>
        <mesh
          filename="package://HERB_BASE_URDF/meshes/segway_right.STL" />
      </geometry>
    </collision>
  </link>
  <joint
    name="segway_right"
    type="continuous">
    <origin
      xyz="0 -0.231771918932663 0.231587356113537"
      rpy="-1.5707963267949 0.0751085369855802 3.14159265358979" />
    <parent
      link="herb_base" />
    <child
      link="segway_right" />
    <axis
      xyz="0 0 1" />
  </joint>
  <link
    name="head_pan">
    <inertial>
      <origin
        xyz="-0.000143379867888344 0.0221150249825214 0.0159634421249915"
        rpy="0 0 0" />
      <mass
        value="0.699914058257394" />
      <inertia
        ixx="0.0028064638409931"
        ixy="-6.06589910190296E-06"
        ixz="-1.10356402708701E-06"
        iyy="0.000592185892279803"
        iyz="-0.000170166312219623"
        izz="0.00264000882290309" />
    </inertial>
    <visual>
      <origin
        xyz="0 0 0"
        rpy="0 0 0" />
      <geometry>
        <mesh
          filename="package://HERB_BASE_URDF/meshes/head_pan.STL" />
      </geometry>
      <material
        name="">
        <color
          rgba="0 1 1 1" />
      </material>
    </visual>
    <collision>
      <origin
        xyz="0 0 0"
        rpy="0 0 0" />
      <geometry>
        <mesh
          filename="package://HERB_BASE_URDF/meshes/head_pan.STL" />
      </geometry>
    </collision>
  </link>
  <joint
    name="head_pan"
    type="continuous">
    <origin
      xyz="-0.219074999999998 3.49999999989525E-05 1.2737592"
      rpy="-3.14159265358979 6.12323399573677E-17 -1.22464679914735E-16" />
    <parent
      link="herb_base" />
    <child
      link="head_pan" />
    <axis
      xyz="0 0 -1" />
  </joint>
  <link
    name="head_tilt">
    <inertial>
      <origin
        xyz="0.00676836020340077 0.0512494218238631 0.00803256112914554"
        rpy="0 0 0" />
      <mass
        value="1.54049400601599" />
      <inertia
        ixx="0.0067835645951359"
        ixy="-0.000318213388742608"
        ixz="-0.000190037318422281"
        iyy="0.00662131693308525"
        iyz="-0.000833945040621096"
        izz="0.00344340957107467" />
    </inertial>
    <visual>
      <origin
        xyz="0 0 0"
        rpy="0 0 0" />
      <geometry>
        <mesh
          filename="package://HERB_BASE_URDF/meshes/head_tilt.STL" />
      </geometry>
      <material
        name="">
        <color
          rgba="0.63921568627451 0.63921568627451 0.686274509803922 1" />
      </material>
    </visual>
    <collision>
      <origin
        xyz="0 0 0"
        rpy="0 0 0" />
      <geometry>
        <mesh
          filename="package://HERB_BASE_URDF/meshes/head_tilt.STL" />
      </geometry>
    </collision>
  </link>
  <joint
    name="head_tilt"
    type="continuous">
    <origin
      xyz="0 0 0"
      rpy="-1.5707963267949 6.1232339957243E-17 -4.22021842840164E-14" />
    <parent
      link="head_pan" />
    <child
      link="head_tilt" />
    <axis
      xyz="0 0 -1" />
  </joint>
</robot>
