<robot
  name="HERB_BASE_URDF">
  <link
    name="herb_base">
    <inertial>
      <origin
        xyz="-0.0809070109190441 0.00802979500174428 0.350730944533607"
        rpy="0 0 0" />
      <mass
        value="118.073177712457" />
      <inertia
        ixx="9.67519962999918"
        ixy="-0.109435937013395"
        ixz="-2.47830472086505"
        iyy="10.2624016904412"
        iyz="0.237380904381388"
        izz="5.27444955638408" />
    </inertial>
    <visual>
      <origin
        xyz="0 0 0"
        rpy="0 0 0" />
      <geometry>
        <mesh
          filename="package://HERB_BASE_URDF/meshes/herb_base.STL" />
      </geometry>
      <material
        name="">
        <color
          rgba="0.792156862745098 0.819607843137255 0.933333333333333 1" />
      </material>
    </visual>
    <collision>
      <origin
        xyz="0 0 0"
        rpy="0 0 0" />
      <geometry>
        <mesh
          filename="package://HERB_BASE_URDF/meshes/herb_base.STL" />
      </geometry>
    </collision>
  </link>
  <link
    name="segway_wheel_left">
    <inertial>
      <origin
        xyz="1.46252801536129E-12 4.14215883814961E-12 0.0471293756901144"
        rpy="0 0 0" />
      <mass
        value="6.7355511743555" />
      <inertia
        ixx="0.092576479522193"
        ixy="-2.98851956896575E-06"
        ixz="1.06719826191761E-09"
        iyy="0.0925839088729686"
        iyz="3.02916843462396E-09"
        izz="0.178365793214305" />
    </inertial>
    <visual>
      <origin
        xyz="0 0 0"
        rpy="0 0 0" />
      <geometry>
        <mesh
          filename="package://HERB_BASE_URDF/meshes/segway_wheel_left.STL" />
      </geometry>
      <material
        name="">
        <color
          rgba="0.792156862745098 0.819607843137255 0.933333333333333 1" />
      </material>
    </visual>
    <collision>
      <origin
        xyz="0 0 0"
        rpy="0 0 0" />
      <geometry>
        <mesh
          filename="package://HERB_BASE_URDF/meshes/segway_wheel_left.STL" />
      </geometry>
    </collision>
  </link>
  <joint
    name="segway_wheel_left"
    type="continuous">
    <origin
      xyz="0 0.231771918932663 0.23158735611353"
      rpy="-1.5707963267949 -0.115508699092541 0" />
    <parent
      link="herb_base" />
    <child
      link="segway_wheel_left" />
    <axis
      xyz="0 0 -1" />
  </joint>
  <link
    name="segway_wheel_right">
    <inertial>
      <origin
        xyz="-1.06512021424976E-15 4.39884240144295E-12 0.0471293756901144"
        rpy="0 0 0" />
      <mass
        value="6.7355511743555" />
      <inertia
        ixx="0.0925754265920571"
        ixy="-1.49287030220407E-10"
        ixz="-1.57554479695633E-16"
        iyy="0.0925849618031043"
        iyz="3.21166212929365E-09"
        izz="0.178365793214305" />
    </inertial>
    <visual>
      <origin
        xyz="0 0 0"
        rpy="0 0 0" />
      <geometry>
        <mesh
          filename="package://HERB_BASE_URDF/meshes/segway_wheel_right.STL" />
      </geometry>
      <material
        name="">
        <color
          rgba="0.792156862745098 0.819607843137255 0.933333333333333 1" />
      </material>
    </visual>
    <collision>
      <origin
        xyz="0 0 0"
        rpy="0 0 0" />
      <geometry>
        <mesh
          filename="package://HERB_BASE_URDF/meshes/segway_wheel_right.STL" />
      </geometry>
    </collision>
  </link>
  <joint
    name="segway_wheel_right"
    type="continuous">
    <origin
      xyz="0 -0.231771918932663 0.231587356113537"
      rpy="-1.5707963267949 0.0751085369855802 3.14159265358979" />
    <parent
      link="herb_base" />
    <child
      link="segway_wheel_right" />
    <axis
      xyz="0 0 1" />
  </joint>
  <link
    name="head/wam1">
    <inertial>
      <origin
        xyz="-0.000143379867888288 -0.0221150249825213 -0.0159634421249912"
        rpy="0 0 0" />
      <mass
        value="0.699914058257394" />
      <inertia
        ixx="0.00280646384099311"
        ixy="6.06589910190373E-06"
        ixz="1.103564027087E-06"
        iyy="0.000592185892279804"
        iyz="-0.000170166312219622"
        izz="0.00264000882290309" />
    </inertial>
    <visual>
      <origin
        xyz="0 0 0"
        rpy="0 0 0" />
      <geometry>
        <mesh
          filename="package://HERB_BASE_URDF/meshes/head_wam1.STL" />
      </geometry>
      <material
        name="">
        <color
          rgba="0 1 1 1" />
      </material>
    </visual>
    <collision>
      <origin
        xyz="0 0 0"
        rpy="0 0 0" />
      <geometry>
        <mesh
          filename="package://HERB_BASE_URDF/meshes/head_wam1.STL" />
      </geometry>
    </collision>
  </link>
  <joint
    name="head/wam1"
    type="continuous">
    <origin
      xyz="-0.219074999999998 3.49999999989525E-05 1.2737592"
      rpy="0 0 0" />
    <parent
      link="herb_base" />
    <child
      link="head/wam1" />
    <axis
      xyz="0 0 1" />
  </joint>
  <link
    name="head/wam2">
    <inertial>
      <origin
        xyz="0.0067683602034008 0.0512494218238626 0.0080325611291456"
        rpy="0 0 0" />
      <mass
        value="1.54049400601598" />
      <inertia
        ixx="0.00678356459513589"
        ixy="-0.000318213388742604"
        ixz="-0.000190037318422283"
        iyy="0.00662131693308524"
        iyz="-0.000833945040621096"
        izz="0.00344340957107467" />
    </inertial>
    <visual>
      <origin
        xyz="0 0 0"
        rpy="0 0 0" />
      <geometry>
        <mesh
          filename="package://HERB_BASE_URDF/meshes/head_wam2.STL" />
      </geometry>
      <material
        name="">
        <color
          rgba="0.63921568627451 0.63921568627451 0.686274509803922 1" />
      </material>
    </visual>
    <collision>
      <origin
        xyz="0 0 0"
        rpy="0 0 0" />
      <geometry>
        <mesh
          filename="package://HERB_BASE_URDF/meshes/head_wam2.STL" />
      </geometry>
    </collision>
  </link>
  <joint
    name="head/wam2"
    type="continuous">
    <origin
      xyz="0 0 0"
      rpy="1.5707963267949 0 4.20797196041016E-14" />
    <parent
      link="head/wam1" />
    <child
      link="head/wam2" />
    <axis
      xyz="0 0 -1" />
  </joint>
</robot>
