<robot xmlns:xacro="http://www.ros.org/wiki/xacro" name="herb_base">
  <xacro:macro name="herb_base" params="prefix">
    <link name="${prefix}/herb_base">
      <inertial>
        <origin xyz="-0.0809027982480422 0.00803042872866252 0.350693951417865" rpy="0 0 0"/>
        <mass value="118.064183849969"/>
        <inertia
            ixx="9.67307679892718" ixy="-0.109440074935232" ixz="-2.47806317387667"
            iyx="0.00000000000000" iyy="10.2602519302075"   iyz="0.237417248956334"
            izx="0.00000000000000" izy="0.00000000000000"   izz="5.27441929623381"/>
      </inertial>
      <visual>
        <origin xyz="0 0 0" rpy="0 0 0"/>
        <geometry>
          <mesh filename="package://herb_description/meshes/base/herb_base.dae"/>
        </geometry>
        <material name="">
          <color rgba="0.086 0.408 0.565 1"/>
        </material>
      </visual>
      <collision>
        <geometry>
          <mesh filename="package://herb_description/meshes/base/herb_base_collision.STL"/>
        </geometry>
      </collision>
    </link>
    <link name="${prefix}/segway_wheel_left">
      <inertial>
        <origin xyz="1.46252801536129E-12 4.14215883814961E-12 0.0471293756901144" rpy="0 0 0"/>
        <mass value="6.7355511743555"/>
        <inertia
            ixx="0.092576479522193" ixy="-2.98851956896402E-06" ixz="1.06719826192435E-09"
            iyx="0.000000000000000" iyy="0.0925839088729686"    iyz="3.02916843456587E-09"
            izx="0.000000000000000" izy="0.0000000000000000"    izz="0.178365793214305"/>
      </inertial>
      <visual>
        <origin xyz="0 0 0" rpy="0 0 0"/>
        <geometry>
          <mesh filename="package://herb_description/meshes/segway/segway_wheel_left.dae"/>
        </geometry>
        <material name="">
          <color rgba="0.2 0.2 0.2 1"/>
        </material>
      </visual>
      <collision>
        <geometry>
          <mesh filename="package://herb_description/meshes/segway/segway_wheel_left_collision.STL"/>
        </geometry>
      </collision>
    </link>
    <joint name="${prefix}/segway_wheel_left" type="continuous">
      <origin xyz="0 0.231771918932663 0.23158735611353" rpy="-1.5707963267949 -0.115508699092541 0"/>
      <parent link="${prefix}/herb_base"/>
      <child link="${prefix}/segway_wheel_left"/>
      <axis xyz="0 0 -1"/>
    </joint>
    <link name="${prefix}/segway_wheel_right">
      <inertial>
        <origin xyz="-1.06512021424976E-15 4.39884240144295E-12 0.0471293756901144" rpy="0 0 0"/>
        <mass value="6.7355511743555"/>
        <inertia
            ixx="0.0925754265920571" ixy="-1.49287030220407E-10" ixz="-1.57504574648507E-16"
            iyx="0.0000000000000000" iyy="0.0925849618031043"    iyz="3.21166212934922E-09"
            izx="0.0000000000000000" izy="0.0000000000000000"    izz="0.178365793214305"/>
      </inertial>
      <visual>
        <origin xyz="0 0 0" rpy="0 0 0"/>
        <geometry>
          <mesh filename="package://herb_description/meshes/segway/segway_wheel_right.dae"/>
        </geometry>
        <material name="">
          <color rgba="0.2 0.2 0.2 1"/>
        </material>
      </visual>
      <collision>
        <geometry>
          <mesh filename="package://herb_description/meshes/segway/segway_wheel_right_collision.STL"/>
        </geometry>
      </collision>
    </link>
    <joint name="${prefix}/segway_wheel_right" type="continuous">
      <origin xyz="0 -0.231771918932663 0.231587356113537" rpy="-1.5707963267949 0.0751085369855802 3.14159265358979"/>
      <parent link="${prefix}/herb_base"/>
      <child link="${prefix}/segway_wheel_right"/>
      <axis xyz="0 0 1"/>
    </joint>
    <link name="${prefix}/head/wam1">
      <inertial>
        <origin xyz="-0.000143379867888344 -0.0221150249825213 -0.0159634421249915" rpy="0 0 0"/>
        <mass value="0.699914058257394"/>
        <inertia
            ixx="0.00280646384099311" ixy="6.06589910190362E-06" ixz="1.10356402708704E-06"
            iyx="0.00000000000000000" iyy="0.000592185892279803" iyz="-0.000170166312219621"
            izx="0.00000000000000000" izy="0.000000000000000000" izz="0.00264000882290309"/>
      </inertial>
      <visual>
        <origin xyz="0 0 0" rpy="0 0 0"/>
        <geometry>
          <mesh filename="package://herb_description/meshes/head/head_wam1.dae"/>
        </geometry>
        <material name="">
          <color rgba="0.086 0.408 0.565 1"/>
        </material>
      </visual>
      <collision>
        <geometry>
        <mesh filename="package://herb_description/meshes/head/head_wam1_collision.STL"/></geometry>
      </collision>
    </link>
    <joint name="${prefix}/head/wam1" type="fixed">
      <origin xyz="-0.219043 0 1.282513" rpy="0 0 0"/>
      <parent link="${prefix}/herb_base"/>
      <child link="${prefix}/head/wam1"/>
      <axis xyz="0 0 1"/>
    </joint>
    <link name="${prefix}/head/wam2">
      <inertial>
        <origin xyz="0.00676836020340077 0.0512494218238631 0.00803256112914554" rpy="0 0 0"/>
        <mass value="1.54049400601599"/>
        <inertia
            ixx="0.0067835645951359" ixy="-0.000318213388742608" ixz="-0.000190037318422281"
            iyx="0.0000000000000000" iyy="0.00662131693308525"   iyz="-0.000833945040621095"
            izx="0.0000000000000000" izy="0.00000000000000000"   izz="0.00344340957107467"/>
      </inertial>
      <visual>
        <origin xyz="0 0 0" rpy="0 0 0"/>
        <geometry>
          <mesh filename="package://herb_description/meshes/head/head_wam2.dae"/>
        </geometry>
        <material name="">
          <color rgba="0.63921568627451 0.63921568627451 0.686274509803922 1"/>
        </material>
      </visual>
      <collision>
        <geometry>
        <mesh filename="package://herb_description/meshes/head/head_wam2_collision.STL"/></geometry>
      </collision>
    </link>
    <joint name="${prefix}/head/wam2" type="fixed">
      <origin xyz="0 0 0" rpy="1.5707963267949 0.3 4.20797196041016E-14"/>
      <parent link="${prefix}/head/wam1"/>
      <child link="${prefix}/head/wam2"/>
      <axis xyz="0 0 1"/>
    </joint>
  </xacro:macro>
</robot>
