<robot
  name="WAM_URDF">
  <link
    name="wam_base">
    <inertial>
      <origin
        xyz="0.128100378751 0.140050620353168 0.0674748862235675"
        rpy="0 0 0" />
      <mass
        value="2.67334422899553" />
      <inertia
        ixx="0.0339063248578931"
        ixy="-1.70259359224025E-05"
        ixz="-0.00415581153259521"
        iyy="0.0421275847678089"
        iyz="-4.62615890481681E-06"
        izz="0.0554123689090636" />
    </inertial>
    <visual>
      <origin
        xyz="0 0 0"
        rpy="0 0 0" />
      <geometry>
        <mesh
          filename="package://WAM_URDF/meshes/wam_base.STL" />
      </geometry>
      <material
        name="">
        <color
          rgba="0.792156862745098 0.819607843137255 0.933333333333333 1" />
      </material>
    </visual>
    <collision>
      <origin
        xyz="0 0 0"
        rpy="0 0 0" />
      <geometry>
        <mesh
          filename="package://WAM_URDF/meshes/wam_base.STL" />
      </geometry>
    </collision>
  </link>
  <link
    name="wam1">
    <inertial>
      <origin
        xyz="2.47322933901508E-08 -2.96918585757471E-09 -0.0794969740283547"
        rpy="0 0 0" />
      <mass
        value="12.6535414859626" />
      <inertia
        ixx="0.199822402581019"
        ixy="8.47009166965951E-08"
        ixz="-3.73911497638795E-08"
        iyy="0.107087726204064"
        iyz="2.75172142172852E-09"
        izz="0.171850063229757" />
    </inertial>
    <visual>
      <origin
        xyz="0 0 0"
        rpy="0 0 0" />
      <geometry>
        <mesh
          filename="package://WAM_URDF/meshes/wam1.STL" />
      </geometry>
      <material
        name="">
        <color
          rgba="0.792156862745098 0.819607843137255 0.933333333333333 1" />
      </material>
    </visual>
    <collision>
      <origin
        xyz="0 0 0"
        rpy="0 0 0" />
      <geometry>
        <mesh
          filename="package://WAM_URDF/meshes/wam1.STL" />
      </geometry>
    </collision>
  </link>
  <joint
    name="j1"
    type="continuous">
    <origin
      xyz="0.22 0.14 0.346"
      rpy="-1.1127E-16 0 0" />
    <parent
      link="wam_base" />
    <child
      link="wam1" />
    <axis
      xyz="0 0 1" />
  </joint>
  <link
    name="wam2">
    <inertial>
      <origin
        xyz="-1.68500531003605E-06 -0.0504690286262691 1.03171858172289E-06"
        rpy="0 0 0" />
      <mass
        value="0.437815219798136" />
      <inertia
        ixx="0.00161441364764365"
        ixy="-3.33213428008851E-08"
        ixz="-3.42708638284836E-08"
        iyy="0.00132132178685251"
        iyz="-8.89408494106095E-09"
        izz="0.00183374073419955" />
    </inertial>
    <visual>
      <origin
        xyz="0 0 0"
        rpy="0 0 0" />
      <geometry>
        <mesh
          filename="package://WAM_URDF/meshes/wam2.STL" />
      </geometry>
      <material
        name="">
        <color
          rgba="0.792156862745098 0.819607843137255 0.933333333333333 1" />
      </material>
    </visual>
    <collision>
      <origin
        xyz="0 0 0"
        rpy="0 0 0" />
      <geometry>
        <mesh
          filename="package://WAM_URDF/meshes/wam2.STL" />
      </geometry>
    </collision>
  </link>
  <joint
    name="j2"
    type="continuous">
    <origin
      xyz="0 0 0"
      rpy="-1.5708 -4.0281E-16 -3.9443E-31" />
    <parent
      link="wam1" />
    <child
      link="wam2" />
    <axis
      xyz="0 0 1" />
  </joint>
  <link
    name="wam3">
    <inertial>
      <origin
        xyz="0.0130868978725475 -9.05815538026002E-06 0.448714683040612"
        rpy="0 0 0" />
      <mass
        value="5.14343147836089E-05" />
      <inertia
        ixx="1.12691041047209E-06"
        ixy="-9.94778283952231E-12"
        ixz="6.55394951197902E-08"
        iyy="1.1140362581574E-06"
        iyz="-4.20859101779289E-11"
        izz="1.08418369812442E-07" />
    </inertial>
    <visual>
      <origin
        xyz="0 0 0"
        rpy="0 0 0" />
      <geometry>
        <mesh
          filename="package://WAM_URDF/meshes/wam3.STL" />
      </geometry>
      <material
        name="">
        <color
          rgba="0.792156862745098 0.819607843137255 0.933333333333333 1" />
      </material>
    </visual>
    <collision>
      <origin
        xyz="0 0 0"
        rpy="0 0 0" />
      <geometry>
        <mesh
          filename="package://WAM_URDF/meshes/wam3.STL" />
      </geometry>
    </collision>
  </link>
  <joint
    name="j3"
    type="continuous">
    <origin
      xyz="0 0 0"
      rpy="1.5708 -3.9443E-31 4.0281E-16" />
    <parent
      link="wam2" />
    <child
      link="wam3" />
    <axis
      xyz="0 0 1" />
  </joint>
  <link
    name="wam4">
    <inertial>
      <origin
        xyz="-0.0431264796810621 -0.150741212865866 -0.000130358703817749"
        rpy="0 0 0" />
      <mass
        value="1.53559449158938" />
      <inertia
        ixx="0.00884513150794336"
        ixy="0.000443161529933271"
        ixz="3.72171152601307E-07"
        iyy="0.00173788879693172"
        iyz="9.82700862828562E-06"
        izz="0.00890058241554246" />
    </inertial>
    <visual>
      <origin
        xyz="0 0 0"
        rpy="0 0 0" />
      <geometry>
        <mesh
          filename="package://WAM_URDF/meshes/wam4.STL" />
      </geometry>
      <material
        name="">
        <color
          rgba="0.792156862745098 0.819607843137255 0.933333333333333 1" />
      </material>
    </visual>
    <collision>
      <origin
        xyz="0 0 0"
        rpy="0 0 0" />
      <geometry>
        <mesh
          filename="package://WAM_URDF/meshes/wam4.STL" />
      </geometry>
    </collision>
  </link>
  <joint
    name="j4"
    type="continuous">
    <origin
      xyz="0.045 0 0.55"
      rpy="-1.5708 0 0" />
    <parent
      link="wam3" />
    <child
      link="wam4" />
    <axis
      xyz="0 0 1" />
  </joint>
  <link
    name="wam5">
    <inertial>
      <origin
        xyz="-1.89899193874971E-08 6.8742965390916E-14 0.291553583928998"
        rpy="0 0 0" />
      <mass
        value="0.149006334634453" />
      <inertia
        ixx="6.71209654106184E-05"
        ixy="-4.97920688322939E-11"
        ixz="-8.15221637559746E-11"
        iyy="8.68252417088456E-05"
        iyz="-8.32554057742882E-12"
        izz="8.70771750035721E-05" />
    </inertial>
    <visual>
      <origin
        xyz="0 0 0"
        rpy="0 0 0" />
      <geometry>
        <mesh
          filename="package://WAM_URDF/meshes/wam5.STL" />
      </geometry>
      <material
        name="">
        <color
          rgba="0.792156862745098 0.819607843137255 0.933333333333333 1" />
      </material>
    </visual>
    <collision>
      <origin
        xyz="0 0 0"
        rpy="0 0 0" />
      <geometry>
        <mesh
          filename="package://WAM_URDF/meshes/wam5.STL" />
      </geometry>
    </collision>
  </link>
  <joint
    name="j5"
    type="continuous">
    <origin
      xyz="-0.045 0 0"
      rpy="1.5708 0 0" />
    <parent
      link="wam4" />
    <child
      link="wam5" />
    <axis
      xyz="0 0 1" />
  </joint>
  <link
    name="wam6">
    <inertial>
      <origin
        xyz="9.92879554891748E-08 -0.0240107071927176 -0.00776584967676938"
        rpy="0 0 0" />
      <mass
        value="0.186433706842734" />
      <inertia
        ixx="0.000275140565643375"
        ixy="6.68240024010672E-11"
        ixz="8.93700712222219E-10"
        iyy="0.000229085870839595"
        iyz="5.89760695551255E-06"
        izz="0.000135295072223808" />
    </inertial>
    <visual>
      <origin
        xyz="0 0 0"
        rpy="0 0 0" />
      <geometry>
        <mesh
          filename="package://WAM_URDF/meshes/wam6.STL" />
      </geometry>
      <material
        name="">
        <color
          rgba="0.792156862745098 0.819607843137255 0.933333333333333 1" />
      </material>
    </visual>
    <collision>
      <origin
        xyz="0 0 0"
        rpy="0 0 0" />
      <geometry>
        <mesh
          filename="package://WAM_URDF/meshes/wam6.STL" />
      </geometry>
    </collision>
  </link>
  <joint
    name="j6"
    type="continuous">
    <origin
      xyz="0 0 0.3"
      rpy="-1.5708 0 0" />
    <parent
      link="wam5" />
    <child
      link="wam6" />
    <axis
      xyz="0 0 1" />
  </joint>
  <link
    name="wam7">
    <inertial>
      <origin
        xyz="3.91693859420655E-17 6.83546172795402E-18 0.0631914020340758"
        rpy="0 0 0" />
      <mass
        value="0.110863010879355" />
      <inertia
        ixx="6.36716939587249E-05"
        ixy="2.16861613083641E-36"
        ixz="-1.06759060945362E-20"
        iyy="6.36716939587249E-05"
        iyz="1.2820004326111E-21"
        izz="0.00012027473419511" />
    </inertial>
    <visual>
      <origin
        xyz="0 0 0"
        rpy="0 0 0" />
      <geometry>
        <mesh
          filename="package://WAM_URDF/meshes/wam7.STL" />
      </geometry>
      <material
        name="">
        <color
          rgba="0.792156862745098 0.819607843137255 0.933333333333333 1" />
      </material>
    </visual>
    <collision>
      <origin
        xyz="0 0 0"
        rpy="0 0 0" />
      <geometry>
        <mesh
          filename="package://WAM_URDF/meshes/wam7.STL" />
      </geometry>
    </collision>
  </link>
  <joint
    name="j7"
    type="continuous">
    <origin
      xyz="0 0 0"
      rpy="1.5708 0 0" />
    <parent
      link="wam6" />
    <child
      link="wam7" />
    <axis
      xyz="0 0 1" />
  </joint>
</robot>