<robot
  name="WAM_URDF">
  <link
    name="wam_base">
    <inertial>
      <origin
        xyz="0.128100378751 0.140050620353168 0.0674748862235675"
        rpy="0 0 0" />
      <mass
        value="2.67334422899553" />
      <inertia
        ixx="0.0339063248578932"
        ixy="-1.70259359224035E-05"
        ixz="-0.00415581153259521"
        iyy="0.0421275847678089"
        iyz="-4.62615890481674E-06"
        izz="0.0554123689090637" />
    </inertial>
    <visual>
      <origin
        xyz="0 0 0"
        rpy="0 0 0" />
      <geometry>
        <mesh
          filename="package://WAM_URDF/meshes/wam_base.STL" />
      </geometry>
      <material
        name="">
        <color
          rgba="1 0 0 0.0499999999999999" />
      </material>
    </visual>
    <collision>
      <origin
        xyz="0 0 0"
        rpy="0 0 0" />
      <geometry>
        <mesh
          filename="package://WAM_URDF/meshes/wam_base.STL" />
      </geometry>
    </collision>
  </link>
  <link
    name="wam1">
    <inertial>
      <origin
        xyz="2.47322933844609E-08 -2.96918585731233E-09 -0.0794969740283547"
        rpy="0 0 0" />
      <mass
        value="12.6535414859626" />
      <inertia
        ixx="0.199822402581019"
        ixy="8.47009166940369E-08"
        ixz="-3.73911497613376E-08"
        iyy="0.107087726204064"
        iyz="2.75172141087821E-09"
        izz="0.171850063229757" />
    </inertial>
    <visual>
      <origin
        xyz="0 0 0"
        rpy="0 0 0" />
      <geometry>
        <mesh
          filename="package://WAM_URDF/meshes/wam1.STL" />
      </geometry>
      <material
        name="">
        <color
          rgba="0.501960784313725 0.501960784313725 0.501960784313725 0.0499999999999999" />
      </material>
    </visual>
    <collision>
      <origin
        xyz="0 0 0"
        rpy="0 0 0" />
      <geometry>
        <mesh
          filename="package://WAM_URDF/meshes/wam1.STL" />
      </geometry>
    </collision>
  </link>
  <joint
    name="j1"
    type="continuous">
    <origin
      xyz="0.22 0.14 0.346"
      rpy="-1.11266916865798E-16 0 0" />
    <parent
      link="wam_base" />
    <child
      link="wam1" />
    <axis
      xyz="0 0 -1" />
  </joint>
  <link
    name="wam2">
    <inertial>
      <origin
        xyz="-1.68500531002702E-06 -0.0504690286262691 1.03171858172485E-06"
        rpy="0 0 0" />
      <mass
        value="0.437815219798136" />
      <inertia
        ixx="0.00161441364764365"
        ixy="-3.33213428011121E-08"
        ixz="-3.42708638284544E-08"
        iyy="0.00132132178685251"
        iyz="-8.89408494106879E-09"
        izz="0.00183374073419955" />
    </inertial>
    <visual>
      <origin
        xyz="0 0 0"
        rpy="0 0 0" />
      <geometry>
        <mesh
          filename="package://WAM_URDF/meshes/wam2.STL" />
      </geometry>
      <material
        name="">
        <color
          rgba="0.937254901960784 0.674509803921569 0.113725490196078 1" />
      </material>
    </visual>
    <collision>
      <origin
        xyz="0 0 0"
        rpy="0 0 0" />
      <geometry>
        <mesh
          filename="package://WAM_URDF/meshes/wam2.STL" />
      </geometry>
    </collision>
  </link>
  <joint
    name="j2"
    type="continuous">
    <origin
      xyz="0 0 0"
      rpy="-1.5707963267949 -4.02814495500316E-16 -3.94430452610506E-31" />
    <parent
      link="wam1" />
    <child
      link="wam2" />
    <axis
      xyz="0 0 -1" />
  </joint>
  <link
    name="wam3">
    <inertial>
      <origin
        xyz="0.0130868978725476 -9.05815538026242E-06 0.448714683040611"
        rpy="0 0 0" />
      <mass
        value="5.1434314783609E-05" />
      <inertia
        ixx="1.12691041047209E-06"
        ixy="-9.94778283952839E-12"
        ixz="6.55394951197899E-08"
        iyy="1.1140362581574E-06"
        iyz="-4.20859101779461E-11"
        izz="1.08418369812442E-07" />
    </inertial>
    <visual>
      <origin
        xyz="0 0 0"
        rpy="0 0 0" />
      <geometry>
        <mesh
          filename="package://WAM_URDF/meshes/wam3.STL" />
      </geometry>
      <material
        name="">
        <color
          rgba="0.501960784313725 1 1 1" />
      </material>
    </visual>
    <collision>
      <origin
        xyz="0 0 0"
        rpy="0 0 0" />
      <geometry>
        <mesh
          filename="package://WAM_URDF/meshes/wam3.STL" />
      </geometry>
    </collision>
  </link>
  <joint
    name="j3"
    type="continuous">
    <origin
      xyz="0 0 0"
      rpy="1.5707963267949 -3.94430452610506E-31 4.02814495500316E-16" />
    <parent
      link="wam2" />
    <child
      link="wam3" />
    <axis
      xyz="0 0 1" />
  </joint>
  <link
    name="wam4">
    <inertial>
      <origin
        xyz="-0.0431264796810621 -0.150741212865866 -0.00013035870381775"
        rpy="0 0 0" />
      <mass
        value="1.53559449158938" />
      <inertia
        ixx="0.00884513150794336"
        ixy="0.000443161529933271"
        ixz="3.72171152601308E-07"
        iyy="0.00173788879693172"
        iyz="9.82700862828561E-06"
        izz="0.00890058241554246" />
    </inertial>
    <visual>
      <origin
        xyz="0 0 0"
        rpy="0 0 0" />
      <geometry>
        <mesh
          filename="package://WAM_URDF/meshes/wam4.STL" />
      </geometry>
      <material
        name="">
        <color
          rgba="0 1 0.501960784313725 1" />
      </material>
    </visual>
    <collision>
      <origin
        xyz="0 0 0"
        rpy="0 0 0" />
      <geometry>
        <mesh
          filename="package://WAM_URDF/meshes/wam4.STL" />
      </geometry>
    </collision>
  </link>
  <joint
    name="j4"
    type="continuous">
    <origin
      xyz="0.0450000000000029 0 0.550000000000001"
      rpy="-1.5707963267949 0 0" />
    <parent
      link="wam3" />
    <child
      link="wam4" />
    <axis
      xyz="0 0 1" />
  </joint>
  <link
    name="wam5">
    <inertial>
      <origin
        xyz="-1.89899193870519E-08 6.87439288515465E-14 0.291553583928998"
        rpy="0 0 0" />
      <mass
        value="0.149006334634453" />
      <inertia
        ixx="6.71209654106184E-05"
        ixy="-4.97920688271065E-11"
        ixz="-8.15221637553386E-11"
        iyy="8.68252417088455E-05"
        iyz="-8.32554057843721E-12"
        izz="8.7077175003572E-05" />
    </inertial>
    <visual>
      <origin
        xyz="0 0 0"
        rpy="0 0 0" />
      <geometry>
        <mesh
          filename="package://WAM_URDF/meshes/wam5.STL" />
      </geometry>
      <material
        name="">
        <color
          rgba="0.909803921568627 0.443137254901961 0.0313725490196078 1" />
      </material>
    </visual>
    <collision>
      <origin
        xyz="0 0 0"
        rpy="0 0 0" />
      <geometry>
        <mesh
          filename="package://WAM_URDF/meshes/wam5.STL" />
      </geometry>
    </collision>
  </link>
  <joint
    name="j5"
    type="continuous">
    <origin
      xyz="-0.0449999999999992 0 0"
      rpy="1.5707963267949 0 0" />
    <parent
      link="wam4" />
    <child
      link="wam5" />
    <axis
      xyz="0 0 -1" />
  </joint>
  <link
    name="wam6">
    <inertial>
      <origin
        xyz="9.92879555389195E-08 -0.0240107071927176 -0.00776584967676936"
        rpy="0 0 0" />
      <mass
        value="0.186433706842734" />
      <inertia
        ixx="0.000275140565643375"
        ixy="6.68240023688892E-11"
        ixz="8.93700712018407E-10"
        iyy="0.000229085870839595"
        iyz="5.89760695551252E-06"
        izz="0.000135295072223808" />
    </inertial>
    <visual>
      <origin
        xyz="0 0 0"
        rpy="0 0 0" />
      <geometry>
        <mesh
          filename="package://WAM_URDF/meshes/wam6.STL" />
      </geometry>
      <material
        name="">
        <color
          rgba="0.501960784313725 0.501960784313725 1 1" />
      </material>
    </visual>
    <collision>
      <origin
        xyz="0 0 0"
        rpy="0 0 0" />
      <geometry>
        <mesh
          filename="package://WAM_URDF/meshes/wam6.STL" />
      </geometry>
    </collision>
  </link>
  <joint
    name="j6"
    type="continuous">
    <origin
      xyz="0 0 0.3"
      rpy="-1.5707963267949 0 0" />
    <parent
      link="wam5" />
    <child
      link="wam6" />
    <axis
      xyz="0 0 -1" />
  </joint>
  <link
    name="wam7">
    <inertial>
      <origin
        xyz="5.3423847878948E-19 -3.54682834687552E-18 0.00319140203407464"
        rpy="0 0 0" />
      <mass
        value="0.110863010879355" />
      <inertia
        ixx="6.36716939587248E-05"
        ixy="1.5958000178719E-34"
        ixz="-1.23540333373179E-20"
        iyy="6.36716939587248E-05"
        iyz="-2.33773138495702E-21"
        izz="0.00012027473419511" />
    </inertial>
    <visual>
      <origin
        xyz="0 0 0"
        rpy="0 0 0" />
      <geometry>
        <mesh
          filename="package://WAM_URDF/meshes/wam7.STL" />
      </geometry>
      <material
        name="">
        <color
          rgba="0.501960784313725 1 0.501960784313725 1" />
      </material>
    </visual>
    <collision>
      <origin
        xyz="0 0 0"
        rpy="0 0 0" />
      <geometry>
        <mesh
          filename="package://WAM_URDF/meshes/wam7.STL" />
      </geometry>
    </collision>
  </link>
  <joint
    name="j7"
    type="continuous">
    <origin
      xyz="0 -0.0600000000000009 0"
      rpy="1.5707963267949 0 0" />
    <parent
      link="wam6" />
    <child
      link="wam7" />
    <axis
      xyz="0 0 1" />
  </joint>
</robot>