<robot
  name="WAM_URDF">
  <link
    name="wam0">
    <inertial>
      <origin
        xyz="0.1281 0.14005 0.067475"
        rpy="0 0 0" />
      <mass
        value="2.6733" />
      <inertia
        ixx="0.033906"
        ixy="-1.7026E-05"
        ixz="-0.0041558"
        iyy="0.042128"
        iyz="-4.6262E-06"
        izz="0.055412" />
    </inertial>
    <visual>
      <origin
        xyz="0 0 0"
        rpy="0 0 0" />
      <geometry>
        <mesh
          filename="package://WAM_URDF/meshes/wam0.STL" />
      </geometry>
      <material
        name="">
        <color
          rgba="1 0 0 0.05" />
      </material>
    </visual>
    <collision>
      <origin
        xyz="0 0 0"
        rpy="0 0 0" />
      <geometry>
        <mesh
          filename="package://WAM_URDF/meshes/wam0.STL" />
      </geometry>
    </collision>
  </link>
  <link
    name="wam1">
    <inertial>
      <origin
        xyz="2.47322933838584E-08 -2.969185857496E-09 -0.0794969740283547"
        rpy="0 0 0" />
      <mass
        value="12.6535414859626" />
      <inertia
        ixx="0.199822402581019"
        ixy="8.47009166931226E-08"
        ixz="-3.73911497625684E-08"
        iyy="0.107087726204064"
        iyz="2.75172141313979E-09"
        izz="0.171850063229757" />
    </inertial>
    <visual>
      <origin
        xyz="0 0 0"
        rpy="0 0 0" />
      <geometry>
        <mesh
          filename="package://WAM_URDF/meshes/wam1.STL" />
      </geometry>
      <material
        name="">
        <color
          rgba="0.501960784313725 0.501960784313725 0.501960784313725 0.0499999999999999" />
      </material>
    </visual>
    <collision>
      <origin
        xyz="0 0 0"
        rpy="0 0 0" />
      <geometry>
        <mesh
          filename="package://WAM_URDF/meshes/wam1.STL" />
      </geometry>
    </collision>
  </link>
  <joint
    name="j1"
    type="continuous">
    <origin
      xyz="0.22 0.14 0.346"
      rpy="-1.1127E-16 0 0" />
    <parent
      link="wam0" />
    <child
      link="wam1" />
    <axis
      xyz="0 0 -1" />
  </joint>
  <link
    name="wam2">
    <inertial>
      <origin
        xyz="-1.68500531002702E-06 -0.0504690286262691 1.03171858172485E-06"
        rpy="0 0 0" />
      <mass
        value="0.437815219798136" />
      <inertia
        ixx="0.00161441364764365"
        ixy="-3.33213428011121E-08"
        ixz="-3.42708638284544E-08"
        iyy="0.00132132178685251"
        iyz="-8.89408494106879E-09"
        izz="0.00183374073419955" />
    </inertial>
    <visual>
      <origin
        xyz="0 0 0"
        rpy="0 0 0" />
      <geometry>
        <mesh
          filename="package://WAM_URDF/meshes/wam2.STL" />
      </geometry>
      <material
        name="">
        <color
          rgba="0.937254901960784 0.674509803921569 0.113725490196078 1" />
      </material>
    </visual>
    <collision>
      <origin
        xyz="0 0 0"
        rpy="0 0 0" />
      <geometry>
        <mesh
          filename="package://WAM_URDF/meshes/wam2.STL" />
      </geometry>
    </collision>
  </link>
  <joint
    name="j2"
    type="continuous">
    <origin
      xyz="0 0 0"
      rpy="-1.5708 -4.0281E-16 -3.9443E-31" />
    <parent
      link="wam1" />
    <child
      link="wam2" />
    <axis
      xyz="0 0 -1" />
  </joint>
  <link
    name="wam3">
    <inertial>
      <origin
        xyz="0.013087 -9.0582E-06 0.44871"
        rpy="0 0 0" />
      <mass
        value="5.1434E-05" />
      <inertia
        ixx="1.1269E-06"
        ixy="-9.9478E-12"
        ixz="6.5539E-08"
        iyy="1.114E-06"
        iyz="-4.2086E-11"
        izz="1.0842E-07" />
    </inertial>
    <visual>
      <origin
        xyz="0 0 0"
        rpy="0 0 0" />
      <geometry>
        <mesh
          filename="package://WAM_URDF/meshes/wam3.STL" />
      </geometry>
      <material
        name="">
        <color
          rgba="0.50196 1 1 1" />
      </material>
    </visual>
    <collision>
      <origin
        xyz="0 0 0"
        rpy="0 0 0" />
      <geometry>
        <mesh
          filename="package://WAM_URDF/meshes/wam3.STL" />
      </geometry>
    </collision>
  </link>
  <joint
    name="j3"
    type="continuous">
    <origin
      xyz="0 0 0"
      rpy="1.5707963267949 -3.94430452610506E-31 4.02814495500316E-16" />
    <parent
      link="wam2" />
    <child
      link="wam3" />
    <axis
      xyz="0 0 1" />
  </joint>
  <link
    name="wam4">
    <inertial>
      <origin
        xyz="-0.043126 -0.15074 -0.00013036"
        rpy="0 0 0" />
      <mass
        value="1.5356" />
      <inertia
        ixx="0.0088451"
        ixy="0.00044316"
        ixz="3.7217E-07"
        iyy="0.0017379"
        iyz="9.827E-06"
        izz="0.0089006" />
    </inertial>
    <visual>
      <origin
        xyz="0 0 0"
        rpy="0 0 0" />
      <geometry>
        <mesh
          filename="package://WAM_URDF/meshes/wam4.STL" />
      </geometry>
      <material
        name="">
        <color
          rgba="0 1 0.50196 1" />
      </material>
    </visual>
    <collision>
      <origin
        xyz="0 0 0"
        rpy="0 0 0" />
      <geometry>
        <mesh
          filename="package://WAM_URDF/meshes/wam4.STL" />
      </geometry>
    </collision>
  </link>
  <joint
    name="j4"
    type="continuous">
    <origin
      xyz="0.0450000000000029 0 0.550000000000001"
      rpy="-1.5707963267949 0 0" />
    <parent
      link="wam3" />
    <child
      link="wam4" />
    <axis
      xyz="0 0 1" />
  </joint>
  <link
    name="wam5">
    <inertial>
      <origin
        xyz="-1.89899193872589E-08 6.8742732678153E-14 0.291553583928998"
        rpy="0 0 0" />
      <mass
        value="0.149006334634453" />
      <inertia
        ixx="6.71209654106184E-05"
        ixy="-4.97920688324939E-11"
        ixz="-8.15221637559619E-11"
        iyy="8.68252417088456E-05"
        iyz="-8.32554057768516E-12"
        izz="8.70771750035721E-05" />
    </inertial>
    <visual>
      <origin
        xyz="0 0 0"
        rpy="0 0 0" />
      <geometry>
        <mesh
          filename="package://WAM_URDF/meshes/wam5.STL" />
      </geometry>
      <material
        name="">
        <color
          rgba="0.909803921568627 0.443137254901961 0.0313725490196078 1" />
      </material>
    </visual>
    <collision>
      <origin
        xyz="0 0 0"
        rpy="0 0 0" />
      <geometry>
        <mesh
          filename="package://WAM_URDF/meshes/wam5.STL" />
      </geometry>
    </collision>
  </link>
  <joint
    name="j5"
    type="continuous">
    <origin
      xyz="-0.0449999999999992 0 0"
      rpy="1.5707963267949 0 0" />
    <parent
      link="wam4" />
    <child
      link="wam5" />
    <axis
      xyz="0 0 -1" />
  </joint>
  <link
    name="wam6">
    <inertial>
      <origin
        xyz="9.9288E-08 -0.024011 -0.0077658"
        rpy="0 0 0" />
      <mass
        value="0.18643" />
      <inertia
        ixx="0.00027514"
        ixy="6.6824E-11"
        ixz="8.937E-10"
        iyy="0.00022909"
        iyz="5.8976E-06"
        izz="0.0001353" />
    </inertial>
    <visual>
      <origin
        xyz="0 0 0"
        rpy="0 0 0" />
      <geometry>
        <mesh
          filename="package://WAM_URDF/meshes/wam6.STL" />
      </geometry>
      <material
        name="">
        <color
          rgba="0.50196 0.50196 1 1" />
      </material>
    </visual>
    <collision>
      <origin
        xyz="0 0 0"
        rpy="0 0 0" />
      <geometry>
        <mesh
          filename="package://WAM_URDF/meshes/wam6.STL" />
      </geometry>
    </collision>
  </link>
  <joint
    name="j6"
    type="continuous">
    <origin
      xyz="0 0 0.3"
      rpy="-1.5707963267949 0 0" />
    <parent
      link="wam5" />
    <child
      link="wam6" />
    <axis
      xyz="0 0 -1" />
  </joint>
  <link
    name="wam7">
    <inertial>
      <origin
        xyz="2.392E-19 -2.5244E-29 0.0028873"
        rpy="0 0 0" />
      <mass
        value="0.036704" />
      <inertia
        ixx="2.3961E-05"
        ixy="1.61E-34"
        ixz="-4.9624E-21"
        iyy="2.3961E-05"
        iyz="1.1841E-34"
        izz="4.7306E-05" />
    </inertial>
    <visual>
      <origin
        xyz="0 0 0"
        rpy="0 0 0" />
      <geometry>
        <mesh
          filename="package://WAM_URDF/meshes/wam7.STL" />
      </geometry>
      <material
        name="">
        <color
          rgba="0.50196 1 0.50196 1" />
      </material>
    </visual>
    <collision>
      <origin
        xyz="0 0 0"
        rpy="0 0 0" />
      <geometry>
        <mesh
          filename="package://WAM_URDF/meshes/wam7.STL" />
      </geometry>
    </collision>
  </link>
  <joint
    name="j7"
    type="continuous">
    <origin
      xyz="0 -0.0539500000000008 0"
      rpy="1.5707963267949 0 0" />
    <parent
      link="wam6" />
    <child
      link="wam7" />
    <axis
      xyz="0 0 1" />
  </joint>
</robot>